<?xml version="1.0" encoding="utf-8"?>
<!-- This URDF was automatically created by SolidWorks to URDF Exporter! Originally created by Stephen Brawner (brawner@gmail.com) 
     Commit Version: 1.6.0-4-g7f85cfe  Build Version: 1.6.7995.38578
     For more information, please see http://wiki.ros.org/sw_urdf_exporter -->
<robot
  name="rosaya">
  <link
    name="Link1">
    <inertial>
      <origin
        xyz="-0.014045 -0.00010244 0.42421"
        rpy="0 0 0" />
      <mass
        value="0.26448" />
      <inertia
        ixx="0.00037715"
        ixy="2.5995E-08"
        ixz="8.269E-06"
        iyy="0.00020603"
        iyz="1.6005E-07"
        izz="0.0003378" />
    </inertial>
    <visual>
      <origin
        xyz="0 0 0"
        rpy="0 0 0" />
      <geometry>
        <mesh
          filename="package://rosaya/meshes/Link1.STL" />
      </geometry>
      <material
        name="">
        <color
          rgba="0.75294 0.75294 0.75294 1" />
      </material>
    </visual>
    <collision>
      <origin
        xyz="0 0 0"
        rpy="0 0 0" />
      <geometry>
        <mesh
          filename="package://rosaya/meshes/Link1.STL" />
      </geometry>
    </collision>
  </link>
  <link
    name="Link2">
    <inertial>
      <origin
        xyz="-0.027516 0.00022504 -0.039853"
        rpy="0 0 0" />
      <mass
        value="0.26676" />
      <inertia
        ixx="0.00020194"
        ixy="-2.026E-07"
        ixz="-2.9245E-07"
        iyy="6.9731E-05"
        iyz="-6.7072E-07"
        izz="0.00020891" />
    </inertial>
    <visual>
      <origin
        xyz="0 0 0"
        rpy="0 0 0" />
      <geometry>
        <mesh
          filename="package://rosaya/meshes/Link2.STL" />
      </geometry>
      <material
        name="">
        <color
          rgba="0.75294 0.75294 0.75294 1" />
      </material>
    </visual>
    <collision>
      <origin
        xyz="0 0 0"
        rpy="0 0 0" />
      <geometry>
        <mesh
          filename="package://rosaya/meshes/Link2.STL" />
      </geometry>
    </collision>
  </link>
  <joint
    name="Joint1"
    type="continuous">
    <origin
      xyz="0.0150416145062784 -0.000145225937100715 0.375282029235617"
      rpy="-0.00310746977134566 0 0" />
    <parent
      link="Link1" />
    <child
      link="Link2" />
    <axis
      xyz="1 0 0" />
  </joint>
  <link
    name="Link3">
    <inertial>
      <origin
        xyz="-0.010804 2.1661E-06 -0.024632"
        rpy="0 0 0" />
      <mass
        value="0.14146" />
      <inertia
        ixx="2.3963E-05"
        ixy="2.9004E-09"
        ixz="1.8274E-07"
        iyy="3.8433E-05"
        iyz="-3.819E-11"
        izz="3.167E-05" />
    </inertial>
    <visual>
      <origin
        xyz="0 0 0"
        rpy="0 0 0" />
      <geometry>
        <mesh
          filename="package://rosaya/meshes/Link3.STL" />
      </geometry>
      <material
        name="">
        <color
          rgba="0.75294 0.75294 0.75294 1" />
      </material>
    </visual>
    <collision>
      <origin
        xyz="0 0 0"
        rpy="0 0 0" />
      <geometry>
        <mesh
          filename="package://rosaya/meshes/Link3.STL" />
      </geometry>
    </collision>
  </link>
  <joint
    name="Joint2"
    type="continuous">
    <origin
      xyz="-0.0150417125919951 0.000171249925764887 -0.0551096819554042"
      rpy="0.00310746977134566 0 0" />
    <parent
      link="Link2" />
    <child
      link="Link3" />
    <axis
      xyz="0 0 1" />
  </joint>
  <link
    name="L_Link">
    <inertial>
      <origin
        xyz="2.5032E-07 7.443E-08 -0.0094973"
        rpy="0 0 0" />
      <mass
        value="0.0062048" />
      <inertia
        ixx="1.1671E-06"
        ixy="2.2413E-14"
        ixz="-1.3175E-11"
        iyy="4.7062E-06"
        iyz="-3.9175E-12"
        izz="4.3674E-06" />
    </inertial>
    <visual>
      <origin
        xyz="0 0 0"
        rpy="0 0 0" />
      <geometry>
        <mesh
          filename="package://rosaya/meshes/L_Link.STL" />
      </geometry>
      <material
        name="">
        <color
          rgba="0.75294 0.75294 0.75294 1" />
      </material>
    </visual>
    <collision>
      <origin
        xyz="0 0 0"
        rpy="0 0 0" />
      <geometry>
        <mesh
          filename="package://rosaya/meshes/L_Link.STL" />
      </geometry>
    </collision>
  </link>
  <joint
    name="Joint3"
    type="continuous">
    <origin
      xyz="0 0.045659264836335 -0.0460755308216049"
      rpy="0 0 -0.000200463315012628" />
    <parent
      link="Link3" />
    <child
      link="L_Link" />
    <axis
      xyz="0 0 1" />
  </joint>
  <link
    name="L_Link1">
    <inertial>
      <origin
        xyz="0.00657352061231821 -0.000309348250411443 -0.0151747345156473"
        rpy="0 0 0" />
      <mass
        value="0.186396401372013" />
      <inertia
        ixx="7.83299289692851E-05"
        ixy="3.05121818869238E-12"
        ixz="-1.9591696072584E-07"
        iyy="7.66988314756653E-05"
        iyz="1.61633318765245E-07"
        izz="4.72447757065841E-05" />
    </inertial>
    <visual>
      <origin
        xyz="0 0 0"
        rpy="0 0 0" />
      <geometry>
        <mesh
          filename="package://rosaya/meshes/L_Link1.STL" />
      </geometry>
      <material
        name="">
        <color
          rgba="0.752941176470588 0.752941176470588 0.752941176470588 1" />
      </material>
    </visual>
    <collision>
      <origin
        xyz="0 0 0"
        rpy="0 0 0" />
      <geometry>
        <mesh
          filename="package://rosaya/meshes/L_Link1.STL" />
      </geometry>
    </collision>
  </link>
  <joint
    name="Joint5"
    type="continuous">
    <origin
      xyz="-0.0317500000000014 0 -0.0339141545469447"
      rpy="0.000537539761406673 0 0" />
    <parent
      link="L_Link" />
    <child
      link="L_Link1" />
    <axis
      xyz="1 0 0" />
  </joint>
  <link
    name="L_Link2">
    <inertial>
      <origin
        xyz="-0.00048595 0.024579 -0.091308"
        rpy="0 0 0" />
      <mass
        value="0.099079" />
      <inertia
        ixx="4.9382E-05"
        ixy="-2.9464E-09"
        ixz="-1.1213E-07"
        iyy="3.6564E-05"
        iyz="-1.0628E-06"
        izz="2.8912E-05" />
    </inertial>
    <visual>
      <origin
        xyz="0 0 0"
        rpy="0 0 0" />
      <geometry>
        <mesh
          filename="package://rosaya/meshes/L_Link2.STL" />
      </geometry>
      <material
        name="">
        <color
          rgba="0.75294 0.75294 0.75294 1" />
      </material>
    </visual>
    <collision>
      <origin
        xyz="0 0 0"
        rpy="0 0 0" />
      <geometry>
        <mesh
          filename="package://rosaya/meshes/L_Link2.STL" />
      </geometry>
    </collision>
  </link>
  <joint
    name="Joint7"
    type="continuous">
    <origin
      xyz="0.0317200000000001 -0.0244999999999996 0"
      rpy="0 0 0" />
    <parent
      link="L_Link1" />
    <child
      link="L_Link2" />
    <axis
      xyz="0 1 0" />
  </joint>
  <link
    name="L_Link3">
    <inertial>
      <origin
        xyz="0.00932898247433369 0.026035398000001 -0.0336820846788216"
        rpy="0 0 0" />
      <mass
        value="0.0193582268613659" />
      <inertia
        ixx="3.00375991900623E-05"
        ixy="1.78199519362299E-20"
        ixz="-4.16144772485329E-06"
        iyy="2.14370365193727E-05"
        iyz="1.96376094083954E-19"
        izz="1.54337749522801E-05" />
    </inertial>
    <visual>
      <origin
        xyz="0 0 0"
        rpy="0 0 0" />
      <geometry>
        <mesh
          filename="package://rosaya/meshes/L_Link3.STL" />
      </geometry>
      <material
        name="">
        <color
          rgba="0.752941176470588 0.752941176470588 0.752941176470588 1" />
      </material>
    </visual>
    <collision>
      <origin
        xyz="0 0 0"
        rpy="0 0 0" />
      <geometry>
        <mesh
          filename="package://rosaya/meshes/L_Link3.STL" />
      </geometry>
    </collision>
  </link>
  <joint
    name="Joint9"
    type="continuous">
    <origin
      xyz="-0.000558037765886032 -0.00140000000000197 -0.112828252884564"
      rpy="0 -0.000303003582677282 0" />
    <parent
      link="L_Link2" />
    <child
      link="L_Link3" />
    <axis
      xyz="0 1 0" />
  </joint>
  <link
    name="L_Link4">
    <inertial>
      <origin
        xyz="-0.022933 0.025987 0.015294"
        rpy="0 0 0" />
      <mass
        value="0.18164" />
      <inertia
        ixx="7.5271E-05"
        ixy="9.7469E-14"
        ixz="1.0704E-06"
        iyy="7.4761E-05"
        iyz="-1.0645E-06"
        izz="4.691E-05" />
    </inertial>
    <visual>
      <origin
        xyz="0 0 0"
        rpy="0 0 0" />
      <geometry>
        <mesh
          filename="package://rosaya/meshes/L_Link4.STL" />
      </geometry>
      <material
        name="">
        <color
          rgba="0.75294 0.75294 0.75294 1" />
      </material>
    </visual>
    <collision>
      <origin
        xyz="0 0 0"
        rpy="0 0 0" />
      <geometry>
        <mesh
          filename="package://rosaya/meshes/L_Link4.STL" />
      </geometry>
    </collision>
  </link>
  <joint
    name="Joint11"
    type="continuous">
    <origin
      xyz="0 0 -0.0949999999999996"
      rpy="0 0.000302748335169453 0" />
    <parent
      link="L_Link3" />
    <child
      link="L_Link4" />
    <axis
      xyz="0 1 0" />
  </joint>
  <link
    name="L_Link5">
    <inertial>
      <origin
        xyz="0.02791 0.0078481 -0.029268"
        rpy="0 0 0" />
      <mass
        value="0.072891" />
      <inertia
        ixx="3.332E-05"
        ixy="-2.7125E-14"
        ixz="8.0736E-16"
        iyy="0.00010263"
        iyz="1.6495E-12"
        izz="0.00013288" />
    </inertial>
    <visual>
      <origin
        xyz="0 0 0"
        rpy="0 0 0" />
      <geometry>
        <mesh
          filename="package://rosaya/meshes/L_Link5.STL" />
      </geometry>
      <material
        name="">
        <color
          rgba="0.75294 0.75294 0.75294 1" />
      </material>
    </visual>
    <collision>
      <origin
        xyz="0 0 0"
        rpy="0 0 0" />
      <geometry>
        <mesh
          filename="package://rosaya/meshes/L_Link5.STL" />
      </geometry>
    </collision>
  </link>
  <joint
    name="Joint13"
    type="continuous">
    <origin
      xyz="-0.0236 0.026 0"
      rpy="0 0 0" />
    <parent
      link="L_Link4" />
    <child
      link="L_Link5" />
    <axis
      xyz="1 0 0" />
  </joint>
  <link
    name="R_Link">
    <inertial>
      <origin
        xyz="2.5032E-07 7.443E-08 -0.0094973"
        rpy="0 0 0" />
      <mass
        value="0.0062048" />
      <inertia
        ixx="1.1671E-06"
        ixy="2.2413E-14"
        ixz="-1.3175E-11"
        iyy="4.7062E-06"
        iyz="-3.9175E-12"
        izz="4.3674E-06" />
    </inertial>
    <visual>
      <origin
        xyz="0 0 0"
        rpy="0 0 0" />
      <geometry>
        <mesh
          filename="package://rosaya/meshes/R_Link.STL" />
      </geometry>
      <material
        name="">
        <color
          rgba="0.75294 0.75294 0.75294 1" />
      </material>
    </visual>
    <collision>
      <origin
        xyz="0 0 0"
        rpy="0 0 0" />
      <geometry>
        <mesh
          filename="package://rosaya/meshes/R_Link.STL" />
      </geometry>
    </collision>
  </link>
  <joint
    name="Joint4"
    type="continuous">
    <origin
      xyz="0 -0.0456592648363355 -0.0460755308216101"
      rpy="0 0 -0.000200463315012628" />
    <parent
      link="Link3" />
    <child
      link="R_Link" />
    <axis
      xyz="0 0 1" />
  </joint>
  <link
    name="R_Link1">
    <inertial>
      <origin
        xyz="0.0065753 0.00030936 -0.015175"
        rpy="0 0 0" />
      <mass
        value="0.1864" />
      <inertia
        ixx="7.833E-05"
        ixy="3.0512E-12"
        ixz="-1.9592E-07"
        iyy="7.6699E-05"
        iyz="-1.6213E-07"
        izz="4.7245E-05" />
    </inertial>
    <visual>
      <origin
        xyz="0 0 0"
        rpy="0 0 0" />
      <geometry>
        <mesh
          filename="package://rosaya/meshes/R_Link1.STL" />
      </geometry>
      <material
        name="">
        <color
          rgba="0.75294 0.75294 0.75294 1" />
      </material>
    </visual>
    <collision>
      <origin
        xyz="0 0 0"
        rpy="0 0 0" />
      <geometry>
        <mesh
          filename="package://rosaya/meshes/R_Link1.STL" />
      </geometry>
    </collision>
  </link>
  <joint
    name="Joint6"
    type="continuous">
    <origin
      xyz="-0.0317499999999999 0 -0.0339141545469453"
      rpy="0.000537539765574113 0 0" />
    <parent
      link="R_Link" />
    <child
      link="R_Link1" />
    <axis
      xyz="1 0 0" />
  </joint>
  <link
    name="R_Link2">
    <inertial>
      <origin
        xyz="-2.8011E-05 -0.024579 -0.09126"
        rpy="0 0 0" />
      <mass
        value="0.099079" />
      <inertia
        ixx="4.9383E-05"
        ixy="2.3102E-09"
        ixz="-7.6028E-09"
        iyy="3.6564E-05"
        iyz="1.0628E-06"
        izz="2.8911E-05" />
    </inertial>
    <visual>
      <origin
        xyz="0 0 0"
        rpy="0 0 0" />
      <geometry>
        <mesh
          filename="package://rosaya/meshes/R_Link2.STL" />
      </geometry>
      <material
        name="">
        <color
          rgba="0.75294 0.75294 0.75294 1" />
      </material>
    </visual>
    <collision>
      <origin
        xyz="0 0 0"
        rpy="0 0 0" />
      <geometry>
        <mesh
          filename="package://rosaya/meshes/R_Link2.STL" />
      </geometry>
    </collision>
  </link>
  <joint
    name="Joint8"
    type="continuous">
    <origin
      xyz="0.031720000000165 0.0245000000000003 -4.90873395437297E-05"
      rpy="0 0 0" />
    <parent
      link="R_Link1" />
    <child
      link="R_Link2" />
    <axis
      xyz="0 1 0" />
  </joint>
  <link
    name="R_Link3">
    <inertial>
      <origin
        xyz="0.009329 -0.026035 -0.033682"
        rpy="0 0 0" />
      <mass
        value="0.019358" />
      <inertia
        ixx="3.0038E-05"
        ixy="-2.727E-20"
        ixz="-4.1614E-06"
        iyy="2.1437E-05"
        iyz="1.9102E-19"
        izz="1.5434E-05" />
    </inertial>
    <visual>
      <origin
        xyz="0 0 0"
        rpy="0 0 0" />
      <geometry>
        <mesh
          filename="package://rosaya/meshes/R_Link3.STL" />
      </geometry>
      <material
        name="">
        <color
          rgba="0.75294 0.75294 0.75294 1" />
      </material>
    </visual>
    <collision>
      <origin
        xyz="0 0 0"
        rpy="0 0 0" />
      <geometry>
        <mesh
          filename="package://rosaya/meshes/R_Link3.STL" />
      </geometry>
    </collision>
  </link>
  <joint
    name="Joint10"
    type="continuous">
    <origin
      xyz="0 0.0014000000000008 -0.11278054553733"
      rpy="0 0 0" />
    <parent
      link="R_Link2" />
    <child
      link="R_Link3" />
    <axis
      xyz="0 1 0" />
  </joint>
  <link
    name="R_Link4">
    <inertial>
      <origin
        xyz="-0.02293 -0.02599 0.015294"
        rpy="0 0 0" />
      <mass
        value="0.18164" />
      <inertia
        ixx="7.5271E-05"
        ixy="9.7469E-14"
        ixz="1.0737E-06"
        iyy="7.4761E-05"
        iyz="1.0612E-06"
        izz="4.691E-05" />
    </inertial>
    <visual>
      <origin
        xyz="0 0 0"
        rpy="0 0 0" />
      <geometry>
        <mesh
          filename="package://rosaya/meshes/R_Link4.STL" />
      </geometry>
      <material
        name="">
        <color
          rgba="0.75294 0.75294 0.75294 1" />
      </material>
    </visual>
    <collision>
      <origin
        xyz="0 0 0"
        rpy="0 0 0" />
      <geometry>
        <mesh
          filename="package://rosaya/meshes/R_Link4.STL" />
      </geometry>
    </collision>
  </link>
  <joint
    name="Joint12"
    type="continuous">
    <origin
      xyz="0 0 -0.0949999999999999"
      rpy="0 0 0" />
    <parent
      link="R_Link3" />
    <child
      link="R_Link4" />
    <axis
      xyz="0 1 0" />
  </joint>
  <link
    name="R_Link5">
    <inertial>
      <origin
        xyz="0.02791 -0.0078481 -0.029268"
        rpy="0 0 0" />
      <mass
        value="0.072891" />
      <inertia
        ixx="3.332E-05"
        ixy="-2.7124E-14"
        ixz="8.0731E-16"
        iyy="0.00010263"
        iyz="1.6495E-12"
        izz="0.00013288" />
    </inertial>
    <visual>
      <origin
        xyz="0 0 0"
        rpy="0 0 0" />
      <geometry>
        <mesh
          filename="package://rosaya/meshes/R_Link5.STL" />
      </geometry>
      <material
        name="">
        <color
          rgba="0.75294 0.75294 0.75294 1" />
      </material>
    </visual>
    <collision>
      <origin
        xyz="0 0 0"
        rpy="0 0 0" />
      <geometry>
        <mesh
          filename="package://rosaya/meshes/R_Link5.STL" />
      </geometry>
    </collision>
  </link>
  <joint
    name="Joint14"
    type="continuous">
    <origin
      xyz="-0.0235999999999946 -0.0260000000000017 0"
      rpy="0 0 0" />
    <parent
      link="R_Link4" />
    <child
      link="R_Link5" />
    <axis
      xyz="1 0 0" />
  </joint>
</robot>